Workbook

Sheet الجدول الكامل
A1: الجدول الكامل لتكلفة المطعم (كل البنود)
A2: كل البنود في مكان واحد. التعديل هنا ما يغيّر ورقة الملخص؛ عدّل في ورقة التكلفة التأسيسية.
A4: البند | B4: الكمية | C4: سعر الوحدة | D4: الإجمالي | E4: ملاحظات
A5: معدات الطبخ
A6: شواية/طباخ غاز 6 عيون بدولاب ستيل | B6: 2 | C6: 5000 | D6: =B6*C6 -> 10000 | E6: سعر حصّله صاحب المشروع
A7: قلاية غاز أرضية حوض واحد 28 لتر | B7: 1 | C7: 4600 | D7: =B7*C7 -> 4600 | E7: Elite World GF28L - Ekuep
A8: شفاط ستيل 3م + فلاتر + دكت + مروحة سطح | B8: 1 | C8: 9000 | D8: =B8*C8 -> 9000 | E8: تفصيل ورشة محلية، تقدير
A9: نظام إطفاء آلي فوق الشفاط | B9: 1 | C9: 4000 | D9: =B9*C9 -> 4000 | E9: شرط الدفاع المدني
A10: تمديدات غاز آمنة من الأسطوانات + منظم + حساس تسريب + قفص أسطوانات | B10: 1 | C10: 3000 | D10: =B10*C10 -> 3000
A11: مجموع معدات الطبخ | D11: =SUM(D6:D10) -> 30600
A13: التبريد والتخزين
A14: ثلاجة قائمة ستيل بابين 1140 لتر | B14: 1 | C14: 9460 | D14: =B14*C14 -> 9460 | E14: المصية SMQ-VRS2 - Ekuep؛ صاحب المشروع أكد السعر 9–10 آلاف
A15: فريزر أفقي (صندوق) ~500 لتر | B15: 1 | C15: 2500 | D15: =B15*C15 -> 2500
A16: رف سلك 5 أدوار | B16: 1 | C16: 500 | D16: =B16*C16 -> 500
A17: رف ستيل 5 أدوار | B17: 1 | C17: 900 | D17: =B17*C17 -> 900
A18: مجموع التبريد والتخزين | D18: =SUM(D14:D17) -> 13360
A20: التحضير والغسيل
A21: طاولة تحضير ستيل عريضة 180سم بدور سفلي | B21: 1 | C21: 1200 | D21: =B21*C21 -> 1200 | E21: لتحضير الطعام
A22: رف ستيل للطلبات الجاهزة جنب شباك التطبيقات | B22: 1 | C22: 700 | D22: =B22*C22 -> 700 | E22: يستلم منه مندوب التوصيل
A23: مغسلة ستيل 3 أحواض | B23: 1 | C23: 3500 | D23: =B23*C23 -> 3500 | E23: مو ظاهرة بس شرط بلدية
A24: مصيدة دهون | B24: 1 | C24: 1500 | D24: =B24*C24 -> 1500 | E24: شرط بلدية
A25: أدوات صغيرة: حاويات GN ستيل بأحجام مختلفة | B25: 1 | C25: 800 | D25: =B25*C25 -> 800
A26: أدوات صغيرة: ملاقط وسباتولات وسكاكين | B26: 1 | C26: 600 | D26: =B26*C26 -> 600
A27: أدوات صغيرة: ألواح تقطيع ملونة | B27: 1 | C27: 400 | D27: =B27*C27 -> 400
A28: أدوات صغيرة: علب صوص وموزعات | B28: 1 | C28: 300 | D28: =B28*C28 -> 300
A29: أدوات صغيرة: ميزان + ميزان حرارة طعام | B29: 1 | C29: 500 | D29: =B29*C29 -> 500
A30: مجموع التحضير والغسيل | D30: =SUM(D21:D29) -> 9500
A32: الكاشير والتقنية
A33: نظام كاشير: جهاز كاشير بشاشة لمس | B33: 1 | C33: 2200 | D33: =B33*C33 -> 2200
A34: نظام كاشير: طابعة فواتير | B34: 1 | C34: 800 | D34: =B34*C34 -> 800
A35: نظام كاشير: درج كاش | B35: 1 | C35: 500 | D35: =B35*C35 -> 500
A36: تابلت (طلبات التطبيقات + موظف السيارات) | B36: 1 | C36: 1000 | D36: =B36*C36 -> 1000
A37: كاميرات مراقبة 4 + جهاز تسجيل | B37: 1 | C37: 1500 | D37: =B37*C37 -> 1500 | E37: طقم جاهز
A38: طاولة خشب للكاشير | B38: 1 | C38: 800 | D38: =B38*C38 -> 800
A39: مجموع الكاشير والتقنية | D39: =SUM(D33:D38) -> 6800
A41: التكييف والإضاءة
A42: مكيف سبليت 18 ألف وحدة مع التركيب | B42: 3 | C42: 2400 | D42: =B42*C42 -> 7200 | E42: ماركة اقتصادية جيدة، تقدير
A43: إضاءة داخلية LED بانل | B43: 8 | C43: 120 | D43: =B43*C43 -> 960
A44: إضاءة خارجية (سبوتات + شريط LED للمظلة) | B44: 1 | C44: 1500 | D44: =B44*C44 -> 1500
A45: مجموع التكييف والإضاءة | D45: =SUM(D42:D44) -> 9660
...

Sheet ملاحظات ومتابعة
A1: ملاحظات ومتابعة
A2: الخلاصة: المطلوب للبدء 198,910 ريال، والمصاريف الشهرية الثابتة 18,270 ريال (بدون الإيجار لأنه مدفوع سنوي).
A4: أشياء تتأكد منها قبل ما تصرف
A5: # | B5: البند | C5: ليش مهم | D5: وين تسأل | E5: الحالة
A6: 1 | B6: عرض سعر للواجهة والمظلة (17,000) | C6: أكبر بند تقديري باقي في الحساب | D6: مقاولين كلادينج وحدادة (اثنين على الأقل) | E6: لم يتم
A7: 2 | B7: مغسلة اليدين والسخان | C7: شلناهم من الحساب، والبلدية ممكن تطلبهم حتى لو ما فيه جلسات | D7: البلدية أو مكتب الخدمات اللي يطلع لك الرخصة | E7: لم يتم
A8: 3 | B8: إعفاء المقابل المالي لعاملين | C8: يوفر 1,600 ريال شهريًا؛ لازم تكون متفرغ ومسجل في التأمينات على المطعم، والقرار ما تأكدنا إنه شغال في 2026 | D8: مكتب العمل أو منصة قوى | E8: لم يتم
A9: 4 | B9: العزل المائي ولوحة الكهرباء على المؤجر | C9: شلناهم من الحساب على أساس إنهم على المالك | D9: اكتبها في عقد الإيجار | E9: لم يتم
A11: الخطوات الجاية للمشروع
A12: # | B12: الخطوة | C12: وش نطلع منها
A13: 1 | B13: تكلفة البرجر الواحد | C13: كم يكلف الساندويتش والوجبة بالضبط، وسعر البيع المناسب
A14: 2 | B14: نقطة التعادل | C14: كم وجبة لازم تبيع يوميًا عشان تغطي 18,270 الشهرية وتبدأ تربح
A15: 3 | B15: متى يرجع رأس المال | C15: كم شهر لين ترجع 198,910، على 3 سيناريوهات: ضعيف ومتوسط وقوي
A17: ملاحظة: الأسعار المعلّمة "تقدير سوق" في ورقة التكلفة التأسيسية تقريبية، وتتغير حسب المورد والمدينة.

Sheet الملخص
A1: ملخص تكلفة مشروع المطعم
A3: البند | B3: المبلغ
A4: معدات الطبخ | B4: =SUM('التكلفة التأسيسية'!E5,'التكلفة التأسيسية'!E6,'التكلفة التأسيسية'!E7,'التكلفة التأسيسية'!E8,'التكلفة التأسيسية'!E9) -> 30600
A5: التبريد والتخزين | B5: =SUM('التكلفة التأسيسية'!E10,'التكلفة التأسيسية'!E11,'التكلفة التأسيسية'!E12,'التكلفة التأسيسية'!E13) -> 13360
A6: التحضير والغسيل | B6: =SUM('التكلفة التأسيسية'!E14,'التكلفة التأسيسية'!E15,'التكلفة التأسيسية'!E16,'التكلفة التأسيسية'!E17,'التكلفة التأسيسية'!E18,'التكلفة التأسيسية'!E19) -> 9500
A7: الكاشير والتقنية | B7: =SUM('التكلفة التأسيسية'!E20,'التكلفة التأسيسية'!E21,'التكلفة التأسيسية'!E22,'التكلفة التأسيسية'!E23) -> 6800
A8: التكييف والإضاءة | B8: =SUM('التكلفة التأسيسية'!E24,'التكلفة التأسيسية'!E25,'التكلفة التأسيسية'!E26) -> 9660
A9: الموظفين | B9: =SUM('التكلفة التأسيسية'!E27,'التكلفة التأسيسية'!E28) -> 800
A10: التجهيز والديكور | B10: =SUM('التكلفة التأسيسية'!E29,'التكلفة التأسيسية'!E31,'التكلفة التأسيسية'!E32,'التكلفة التأسيسية'!E33,'التكلفة التأسيسية'!E34,'التكلفة التأسيسية'!E35) -> 46750
A11: التراخيص | B11: =SUM('التكلفة التأسيسية'!E36,'التكلفة التأسيسية'!E37,'التكلفة التأسيسية'!E38,'التكلفة التأسيسية'!E39) -> 5700
A12: ما قبل الافتتاح | B12: =SUM('التكلفة التأسيسية'!E40,'التكلفة التأسيسية'!E41,'التكلفة التأسيسية'!E42,'التكلفة التأسيسية'!E43,'التكلفة التأسيسية'!E44) -> 38000
A13: احتياط (كهرباء وسباكة) | B13: =SUM('التكلفة التأسيسية'!E30) -> 1200
A14: إجمالي التأسيس | B14: =SUM(B4:B13) -> 162370
A16: المصاريف الشهرية الثابتة | B16: ='المصاريف الشهرية'!B15 -> 18270
A17: عدد أشهر الاحتياطي (عدّله) | B17: 2
A18: احتياطي تشغيل (المصاريف الشهرية × عدد الأشهر) | B18: =B16*B17 -> 36540
A20: الإجمالي المطلوب للبدء | B20: =B14+B18 -> 198910

Sheet التكلفة التأسيسية
A1: تكلفة تأسيس مطعم كويك بايت (درايف ثرو)
A2: الأسعار شاملة الضريبة تقريبًا. الخلايا الصفراء (الكمية والسعر) تقدر تعدلها والمجاميع تتحدث تلقائيًا.
A4: القسم | B4: البند | C4: الكمية | D4: سعر الوحدة | E4: الإجمالي | F4: مصدر السعر | G4: ملاحظات
A5: معدات الطبخ | B5: شواية/طباخ غاز 6 عيون بدولاب ستيل | C5: 2 | D5: 5000 | E5: =C5*D5 -> 10000 | F5: سعر حصلته | G5: سعر حصّله صاحب المشروع
A6: معدات الطبخ | B6: قلاية غاز أرضية حوض واحد 28 لتر | C6: 1 | D6: 4600 | E6: =C6*D6 -> 4600 | F6: ✅ سعر متجر | G6: Elite World GF28L - Ekuep
A7: معدات الطبخ | B7: شفاط ستيل 3م + فلاتر + دكت + مروحة سطح | C7: 1 | D7: 9000 | E7: =C7*D7 -> 9000 | F7: تقدير سوق | G7: تفصيل ورشة محلية، تقدير
A8: معدات الطبخ | B8: نظام إطفاء آلي فوق الشفاط | C8: 1 | D8: 4000 | E8: =C8*D8 -> 4000 | F8: سعر حصلته | G8: شرط الدفاع المدني
A9: معدات الطبخ | B9: تمديدات غاز آمنة من الأسطوانات + منظم + حساس تسريب + قفص أسطوانات | C9: 1 | D9: 3000 | E9: =C9*D9 -> 3000 | F9: تقدير سوق
A10: التبريد والتخزين | B10: ثلاجة قائمة ستيل بابين 1140 لتر | C10: 1 | D10: 9460 | E10: =C10*D10 -> 9460 | F10: ✅ سعر متجر | G10: المصية SMQ-VRS2 - Ekuep؛ صاحب المشروع أكد السعر 9–10 آلاف
A11: التبريد والتخزين | B11: فريزر أفقي (صندوق) ~500 لتر | C11: 1 | D11: 2500 | E11: =C11*D11 -> 2500 | F11: تقدير سوق
A12: التبريد والتخزين | B12: رف سلك 5 أدوار | C12: 1 | D12: 500 | E12: =C12*D12 -> 500 | F12: تقدير سوق
A13: التبريد والتخزين | B13: رف ستيل 5 أدوار | C13: 1 | D13: 900 | E13: =C13*D13 -> 900 | F13: تقدير سوق
A14: التحضير والغسيل | B14: طاولة تحضير ستيل عريضة 180سم بدور سفلي | C14: 1 | D14: 1200 | E14: =C14*D14 -> 1200 | F14: تقدير سوق | G14: لتحضير الطعام
A15: التحضير والغسيل | B15: رف ستيل للطلبات الجاهزة جنب شباك التطبيقات | C15: 1 | D15: 700 | E15: =C15*D15 -> 700 | F15: تقدير سوق | G15: يستلم منه مندوب التوصيل
A16: التحضير والغسيل | B16: مغسلة ستيل 3 أحواض | C16: 1 | D16: 3500 | E16: =C16*D16 -> 3500 | F16: تقدير سوق | G16: مو ظاهرة بس شرط بلدية
A17: التحضير والغسيل | B17: مغسلة يدين | C17: 0 | D17: 600 | E17: =C17*D17 -> 0 | F17: تقدير سوق | G17: محذوف بطلبك
A18: التحضير والغسيل | B18: مصيدة دهون | C18: 1 | D18: 1500 | E18: =C18*D18 -> 1500 | F18: تقدير سوق | G18: شرط بلدية
A19: التحضير والغسيل | B19: أدوات صغيرة (ملاقط، سكاكين، حاويات GN، ألواح تقطيع...) | C19: 1 | D19: 2600 | E19: =C19*D19 -> 2600 | F19: تقدير سوق
A20: الكاشير والتقنية | B20: نظام كاشير: جهاز واحد + طابعة + درج كاش | C20: 1 | D20: 3500 | E20: =C20*D20 -> 3500 | F20: تقدير سوق | G20: مثل فودكس/ريوان، الاشتراك شهري منفصل
A21: الكاشير والتقنية | B21: تابلت (طلبات التطبيقات + موظف السيارات) | C21: 1 | D21: 1000 | E21: =C21*D21 -> 1000 | F21: تقدير سوق
A22: الكاشير والتقنية | B22: كاميرات مراقبة 4 + جهاز تسجيل | C22: 1 | D22: 1500 | E22: =C22*D22 -> 1500 | F22: تقدير سوق | G22: طقم جاهز
A23: الكاشير والتقنية | B23: طاولة خشب للكاشير | C23: 1 | D23: 800 | E23: =C23*D23 -> 800 | F23: تقدير سوق
A24: التكييف والإضاءة | B24: مكيف سبليت 18 ألف وحدة مع التركيب | C24: 3 | D24: 2400 | E24: =C24*D24 -> 7200 | F24: تقدير سوق | G24: ماركة اقتصادية جيدة، تقدير
A25: التكييف والإضاءة | B25: إضاءة داخلية LED بانل | C25: 8 | D25: 120 | E25: =C25*D25 -> 960 | F25: تقدير سوق
A26: التكييف والإضاءة | B26: إضاءة خارجية (سبوتات + شريط LED للمظلة) | C26: 1 | D26: 1500 | E26: =C26*D26 -> 1500 | F26: تقدير سوق
A27: الموظفين | B27: لوكر معدن 3 أبواب | C27: 0 | D27: 900 | E27: =C27*D27 -> 0 | F27: تقدير سوق | G27: محذوف بطلبك
A28: الموظفين | B28: زي موظفين (تيشيرت + كاب + مريلة) | C28: 8 | D28: 100 | E28: =C28*D28 -> 800 | F28: تقدير سوق | G28: طقمين لكل موظف
A29: التجهيز والديكور | B29: تبليط ~100م² شامل النعلات والزوايا والدهان + قاطع وباب | C29: 1 | D29: 13000 | E29: =C29*D29 -> 13000 | F29: سعر حصلته للتبليط | G29: السقف موجود؛ العزل على المؤجر
A30: احتياط | B30: احتياط كهرباء وسباكة (يُصرف عند الحاجة) | C30: 1 | D30: 1200 | E30: =C30*D30 -> 1200 | F30: تقدير سوق | G30: مو مصروف أكيد
A31: التجهيز والديكور | B31: تكسية الواجهة الأمامية كلادينج + مظلة | C31: 1 | D31: 17000 | E31: =C31*D31 -> 17000 | F31: تقدير سوق | G31: تفصيلها في ورقة تفصيل الديكور
A32: التجهيز والديكور | B32: لوحة اسم مضيئة | C32: 1 | D32: 6000 | E32: =C32*D32 -> 6000 | F32: تقدير سوق
A33: التجهيز والديكور | B33: شباك درايف ثرو + شباك تطبيقات ألمنيوم | C33: 1 | D33: 6000 | E33: =C33*D33 -> 6000 | F33: تقدير سوق
A34: التجهيز والديكور | B34: لوحات المواقف 1–4 + لوحة طلبات + لوحة التطبيقات | C34: 1 | D34: 1750 | E34: =C34*D34 -> 1750 | F34: تقدير سوق
A35: التجهيز والديكور | B35: مخططات هندسية للبلدية والدفاع المدني | C35: 1 | D35: 3000 | E35: =C35*D35 -> 3000 | F35: تقدير سوق
A36: التراخيص | B36: سجل تجاري + غرفة تجارية | C36: 1 | D36: 1500 | E36: =C36*D36 -> 1500 | F36: تقدير سوق
A37: التراخيص | B37: رخصة بلدية + لوحة | C37: 1 | D37: 2000 | E37: =C37*D37 -> 2000 | F37: تقدير سوق | G37: تختلف حسب المدينة والمساحة
A38: التراخيص | B38: تصريح الدفاع المدني | C38: 1 | D38: 1000 | E38: =C38*D38 -> 1000 | F38: تقدير سوق
A39: التراخيص | B39: شهادات صحية للموظفين | C39: 4 | D39: 300 | E39: =C39*D39 -> 1200 | F39: تقدير سوق
A40: ما قبل الافتتاح | B40: إيجار سنة مقدم | C40: 1 | D40: 20000 | E40: =C40*D40 -> 20000 | F40: منك | G40: من غير الديكور
A41: ما قبل الافتتاح | B41: سعي/عمولة مكتب عقار 2.5% | C41: 0 | D41: 500 | E41: =C41*D41 -> 0 | F41: تقدير سوق | G41: إيجار من المالك مباشرة
...

Sheet المصاريف الشهرية
A1: المصاريف الشهرية الثابتة
A2: ما تشمل تكلفة البضاعة ولا عمولة تطبيقات التوصيل لأنها تتغير حسب المبيعات.
A4: البند | B4: شهريًا | C4: ملاحظات
A5: رواتب 4 موظفين (شوّاي رئيسي 2,500 + 3 موظفين × 2,000) | B5: 8500
A6: المقابل المالي للعمالة الوافدة (800 × 2، والاثنين الباقين معفيين) | B6: 1600 | C6: إعفاء المنشآت الصغيرة: عاملين إذا المالك متفرغ ومسجل في التأمينات، و4 إذا فيه موظف سعودي
A7: سكن الموظفين (400 × 4) | B7: 1600 | C7: تقدير
A8: تأمين طبي (125 × 4) | B8: 500 | C8: تقدير
A9: تأمينات اجتماعية - أخطار مهنية 2% | B9: 170
A10: كهرباء + ماء + غاز | B10: 3000
A11: اشتراك نظام الكاشير | B11: 400
A12: تسويق شهري | B12: 2000
A13: صيانة ونظافة | B13: 500
A15: إجمالي المصاريف الشهرية الثابتة (الإيجار مدفوع سنوي في التأسيس) | B15: =SUM(B5:B13) -> 18270

Sheet الافتراضات
A1: الافتراضات والملاحظات
A2: 1. الشوايات غاز بجودة متوسطة (حسب طلبك).
A3: 2. الإيجار 20,000 ريال، افترضت إنه سنوي ومدفوع مقدم. لو الدفع على دفعات قلّ المبلغ المطلوب للبدء.
A4: 3. المحل مستأجر بدون ديكور، فحسبت التجهيز الداخلي والواجهة على مساحة تقريبية 35م².
A5: 4. الأسعار المعلّمة "سعر متجر" من موقع Ekuep (أكتوبر 2026). الباقي تقدير من أدلة السوق السعودي، والأسعار الفعلية تتغير حسب المورد والمدينة.
A6: 5. ما حسبت تكاليف استقدام موظفين أو نقل كفالة.
A7: 6. ما حسبت تكلفة البضاعة الشهرية ولا عمولة التطبيقات (20–25% تقريبًا من مبيعات التطبيقات) لأنها تعتمد على المبيعات.
A8: 7. أجهزة الدفع (مدى) غالبًا مجانية من البنك أو مزوّد الخدمة مقابل نسبة من العملية.
A10: المصادر:
A11: https://www.ekuep.com/en/alwatania-factory-ov6-220-6-burners-gas-stove-cast-iron-2200-mm
A12: https://www.ekuep.com/en/elite-world-gf28l-gas-fryer-1-basin-28l-capicity
A13: https://www.ekuep.com/en/al-maseya-smq-vrs2-vertical-refrigerator-2-steel-doors
... A1019: 9. إعفاء المقابل المالي لعاملين (المالك متفرغ ومسجل في التأمينات). المصدر: https://www.hrsd.gov.sa/media-center/news/503970

Sheet تفصيل الديكور
A1: تفصيل التجهيز والديكور (تقديري)
A3: تبليط وتشطيب داخلي (~35م²)
A4: تبليط جدران وأرضية ~100م² شامل المواد والمصنعية (سعر حصلته) | B4: 10000
A5: بورسلان أرضية (داخل بند التبليط) | B5: 0
A6: سقف جبس (موجود في المحل) | B6: 0
A7: قاطع داخلي بين المطبخ والكاشير + باب واحد | B7: 3000
A8: عزل مائي وتسوية أرضية (صبّة) (على المؤجر) | B8: 0
A9: نعلات وزوايا ودهان (داخل بند التبليط) | B9: 0
A10: مصنعية التبليط (داخل بند التبليط) | B10: 0
A11: المجموع | B11: =SUM(B4:B10) -> 13000
A13: كهرباء وسباكة
A14: لوحة كهرباء وقواطع (تتحمل المكيفات والثلاجة) (على المؤجر) | B14: 0
A15: تمديدات وأفياش ونقاط مكيفات | B15: 0
A16: تمديدات ماء وصرف للمغاسل | B16: 0
A17: صفايات أرضية 2 وقطع | B17: 0
A18: مصنعية (نُقلت لبند الاحتياط) | B18: 0
A19: المجموع | B19: =SUM(B14:B18) -> 0
A21: الواجهة والمظلة
A22: كلادينج أحمر ورمادي للواجهة الأمامية فقط | B22: 6000
A23: هيكل المظلة وسقفها (على قد منطقة السيارات) | B23: 5000
A24: أعمدة حديد وتركيب ودهان | B24: 2000
A25: حواف المظلة (الإطار الأصفر) | B25: 1500
A26: مصنعية وسقالات | B26: 2500
A27: المجموع | B27: =SUM(B22:B26) -> 17000
A29: اللوحة المضيئة
A30: لوحة حروف بارزة مضيئة ~5×1.2م | B30: 5000
A31: تركيب وتوصيل كهرباء | B31: 1000
A32: المجموع | B32: =SUM(B30:B31) -> 6000
A34: الشبابيك
A35: شباك درايف ثرو منزلق مع رف استلام | B35: 3500
A36: شباك التطبيقات مع مظلة قماش | B36: 2500
A37: المجموع | B37: =SUM(B35:B36) -> 6000
A39: لوحات الموقع
A40: 5 لوحات على أعمدة (1–4 + طلبات) × 250 | B40: 1250
A41: مصدات عجلات 5 × 150 | B41: 0
A42: ملصق أرضي لمنطقة التطبيقات | B42: 0
A43: لوحة شعارات التطبيقات | B43: 500
A44: المجموع | B44: =SUM(B40:B43) -> 1750
A46: مخططات هندسية
A47: مخططات للبلدية والدفاع المدني | B47: 3000
...

Sheet تكلفة البرجر
A1: تكلفة البرجر الواحد وسعر البيع
A2: كل الخلايا الصفراء افتراضات مبدئية (مو أسعار مؤكدة من مورد). بدّلها بأسعارك الفعلية والباقي يتحدث تلقائيًا.
A4: البند | B4: الكمية | C4: الوحدة | D4: سعر الوحدة | E4: التكلفة | F4: ملاحظات
A5: الساندويتش
A6: قرص لحم برجر | B6: 0.12 | C6: كجم | D6: 40 | E6: =B6*D6 -> 4.8 | F6: افتراض: قرص 120 غ بسعر 40 ر.س/كجم؛ حدّثه بسعر المورد
A7: خبز برجر | B7: 1 | C7: حبة | D7: 0.9 | E7: =B7*D7 -> 0.9 | F7: افتراض
A8: جبن (شريحة) | B8: 1 | C8: شريحة | D8: 0.6 | E8: =B8*D8 -> 0.6 | F8: افتراض
A9: خضار (خس، طماطم، مخلل) | B9: 1 | C9: حصة | D9: 0.5 | E9: =B9*D9 -> 0.5 | F9: افتراض
A10: صوص | B10: 1 | C10: حصة | D10: 0.3 | E10: =B10*D10 -> 0.3 | F10: افتراض
A11: تغليف الساندويتش (علبة + ستيكر) | B11: 1 | C11: حبة | D11: 0.9 | E11: =B11*D11 -> 0.9 | F11: افتراض
A12: تكلفة الساندويتش | E12: =SUM(E6:E11) -> 8
A13: إضافات الوجبة
A14: بطاطس مجمدة | B14: 0.15 | C14: كجم | D14: 7 | E14: =B14*D14 -> 1.05 | F14: افتراض: حصة 150 غ
A15: زيت قلي (حصة) | B15: 1 | C15: حصة | D15: 0.3 | E15: =B15*D15 -> 0.3 | F15: افتراض
A16: علبة بطاطس | B16: 1 | C16: حبة | D16: 0.35 | E16: =B16*D16 -> 0.35 | F16: افتراض
A17: مشروب غازي | B17: 1 | C17: علبة | D17: 1.2 | E17: =B17*D17 -> 1.2 | F17: افتراض
A18: مناديل وعلب صوص صغيرة | B18: 1 | C18: حصة | D18: 0.3 | E18: =B18*D18 -> 0.3 | F18: افتراض
A19: تكلفة إضافات الوجبة | E19: =SUM(E14:E18) -> 3.2
A20: تكلفة الوجبة الكاملة | E20: =E12+E19 -> 11.2
A22: التسعير والمزيج | B22: القيمة | F22: ملاحظات
A23: سعر بيع الساندويتش (شامل الضريبة) | B23: 18 | F23: افتراض: قارنه بأسعار المنافسين في حيّك
A24: سعر بيع الوجبة (شامل الضريبة) | B24: 28 | F24: افتراض
A25: ضريبة القيمة المضافة | B25: 0.15 | F25: النسبة النظامية 15%
A26: عمولة تطبيقات التوصيل | B26: 0.225 | F26: من ملف الافتراضات: 20–25% تقريبًا (نص المنتصف)
A27: نسبة الطلبات عبر التطبيقات | B27: 0.4 | F27: افتراض: الباقي درايف ثرو
A28: نسبة الوجبات من إجمالي الطلبات | B28: 0.6 | F28: افتراض: الباقي ساندويتش فقط
A30: النتائج | B30: القيمة | F30: كيف تنحسب
A31: صافي سعر الساندويتش (بدون ضريبة) | B31: =B23/(1+B25) -> 15.652174 | F31: السعر ÷ 1.15
A32: صافي سعر الوجبة (بدون ضريبة) | B32: =B24/(1+B25) -> 24.347826
A33: نسبة تكلفة البضاعة: الساندويتش | B33: =IF(B31>0,E12/B31,0) -> 0.51111111 | F33: الشائع في المطاعم السريعة تقريبًا 28–35% (تقدير عام، مو رقم مؤكد)
A34: نسبة تكلفة البضاعة: الوجبة | B34: =IF(B32>0,E20/B32,0) -> 0.46
A35: متوسط صافي إيراد الطلب | B35: =B28*B32+(1-B28)*B31 -> 20.869565 | F35: مرجّح بنسبة الوجبات
A36: متوسط تكلفة البضاعة للطلب | B36: =B28*E20+(1-B28)*E12 -> 9.92
A37: متوسط عمولة التطبيقات للطلب | B37: =B35*B27*B26 -> 1.8782609 | F37: العمولة على الطلبات اللي تجي من التطبيقات فقط
A38: مساهمة الطلب الواحد (بعد البضاعة والعمولة) | B38: =B35-B36-B37 -> 9.0713043 | F38: اللي يبقى لتغطية المصاريف الثابتة والربح
A39: نسبة المساهمة من الإيراد | B39: =IF(B35>0,B38/B35,0) -> 0.43466667
A41: ما أدخلت رسوم الدفع الإلكتروني (مدى) ولا زكاة/ضريبة دخل، فالأرباح تقريبية قبلها.

Sheet نقطة التعادل
A1: نقطة التعادل
A2: كم طلب لازم تبيع عشان تغطي المصاريف الشهرية الثابتة.
A4: البند | B4: القيمة | D4: ملاحظات
A5: المصاريف الشهرية الثابتة | B5: ='المصاريف الشهرية'!B15 -> 18270 | D5: من ورقة المصاريف الشهرية (بدون الإيجار لأنه مدفوع سنويًا)
A6: مساهمة الطلب الواحد | B6: ='تكلفة البرجر'!B38 -> 9.0713043 | D6: من ورقة تكلفة البرجر
A7: أيام التشغيل في الشهر | B7: 30 | D7: افتراض
A8: طلبات التعادل شهريًا | B8: =IF(B6>0,ROUNDUP(B5/B6,0),"غير ممكن") -> 2015
A9: طلبات التعادل يوميًا | B9: =IF(ISNUMBER(B8),ROUNDUP(B8/B7,0),"غير ممكن") -> 68
A10: صافي إيراد التعادل شهريًا | B10: =IF(ISNUMBER(B8),B8*'تكلفة البرجر'!B35,"غير ممكن") -> 42052.174 | D10: بدون ضريبة القيمة المضافة
A12: طلبات يوميًا | B12: صافي الإيراد الشهري | C12: الربح / الخسارة الشهرية | D12: ملاحظات
A13: 50 | B13: =A13*$B$7*'تكلفة البرجر'!$B$35 -> 31304.348 | C13: =A13*$B$7*$B$6-$B$5 -> -4663.0435 | D13: الربح هنا قبل راتب المالك (متفرغ ومو محسوب في المصاريف)
A14: 75 | B14: =A14*$B$7*'تكلفة البرجر'!$B$35 -> 46956.522 | C14: =A14*$B$7*$B$6-$B$5 -> 2140.4348 | D14: غيّر أرقام الطلبات الصفراء كيف ما تبي
A15: 100 | B15: =A15*$B$7*'تكلفة البرجر'!$B$35 -> 62608.696 | C15: =A15*$B$7*$B$6-$B$5 -> 8943.913
A16: 125 | B16: =A16*$B$7*'تكلفة البرجر'!$B$35 -> 78260.87 | C16: =A16*$B$7*$B$6-$B$5 -> 15747.391
A17: 150 | B17: =A17*$B$7*'تكلفة البرجر'!$B$35 -> 93913.043 | C17: =A17*$B$7*$B$6-$B$5 -> 22550.87
A18: 200 | B18: =A18*$B$7*'تكلفة البرجر'!$B$35 -> 125217.39 | C18: =A18*$B$7*$B$6-$B$5 -> 36157.826
A19: 250 | B19: =A19*$B$7*'تكلفة البرجر'!$B$35 -> 156521.74 | C19: =A19*$B$7*$B$6-$B$5 -> 49764.783
A20: 300 | B20: =A20*$B$7*'تكلفة البرجر'!$B$35 -> 187826.09 | C20: =A20*$B$7*$B$6-$B$5 -> 63371.739

Sheet استرجاع رأس المال
A1: متى يرجع رأس المال
A2: ثلاثة سيناريوهات حسب عدد الطلبات اليومية. أرقام الطلبات افتراضات مبدئية، مو توقعات مؤكدة.
A4: البند | B4: القيمة | F4: ملاحظات
A5: رأس المال المطلوب للبدء | B5: =الملخص!B20 -> 198910 | F5: من ورقة الملخص (يشمل احتياطي التشغيل)
A6: المصاريف الشهرية الثابتة | B6: ='نقطة التعادل'!B5 -> 18270
A7: مساهمة الطلب الواحد | B7: ='تكلفة البرجر'!B38 -> 9.0713043
A8: أيام التشغيل في الشهر | B8: ='نقطة التعادل'!B7 -> 30 | F8: تتغير من ورقة نقطة التعادل
A10: السيناريو | B10: طلبات يوميًا | C10: الربح الصافي الشهري | D10: أشهر الاسترجاع | E10: سنوات | F10: ملاحظات
A11: ضعيف | B11: 80 | C11: =B11*$B$8*$B$7-$B$6 -> 3501.1304 | D11: =IF(C11>0,ROUNDUP($B$5/C11,0),"ما يرجع") -> 57 | E11: =IF(ISNUMBER(D11),D11/12,"-") -> 4.75 | F11: افتراض: يعتمد على موقعك وزحمة الدرايف ثرو
A12: متوسط | B12: 130 | C12: =B12*$B$8*$B$7-$B$6 -> 17108.087 | D12: =IF(C12>0,ROUNDUP($B$5/C12,0),"ما يرجع") -> 12 | E12: =IF(ISNUMBER(D12),D12/12,"-") -> 1 | F12: افتراض
A13: قوي | B13: 220 | C13: =B13*$B$8*$B$7-$B$6 -> 41600.609 | D13: =IF(C13>0,ROUNDUP($B$5/C13,0),"ما يرجع") -> 5 | E13: =IF(ISNUMBER(D13),D13/12,"-") -> 0.41666667 | F13: افتراض: كمان تأكد المطبخ والشباك يتحملون هالحجم
A15: الحساب يفترض مبيعات ثابتة من أول شهر (بدون فترة تأسيس للزبائن)، وقبل راتب المالك والزكاة/الضريبة.
A16: رأس المال يشمل احتياطي شهرين ما يُصرف كله لو المشروع ماشي، فالاسترجاع الفعلي أسرع شوي.
